Workbook
Name SignupNames: 'Signup Form'!$B$6:$B$202
Name SignupClubs: 'Signup Form'!$C$6:$C$202

Sheet Instructions
B2: Brief Instructions
B5: "Signup Form": recommended data needed from the signup form. There is a small script attatched that can automatically create teams based on given rating so that it can be done *on the day!*
B6: This can be linked to the actual form or the data can just be copied across.
B8: "Teams": edit team names and players on each team *once they have been decided*. Everything should automatically update based on the values in this sheet.
B9: If there are more than five players on a team then, as it is right now, they need to go under one name and share scores...
B11: "Box A, B, C": input score data on the day. Give each player the number of points they get for each sport. If playing doubles have it count for both doubles players?
B12: Again: all team and player names should automatically update once they are changed in the "Teams" sheet.
B14: "Final Scores": the final scores! The data from the "Box A, B, C" sheets is collated and compared with the data from "Signup Form" to match people into clubs.
B16: Protected ranges: this is a precautionary measure to prevent accidents... you should be able to edit everything you need.

Sheet Signup Form
B2: ="ALL SIGNUPS: " & COUNTA(B6:B151) -> ALL SIGNUPS: 4 | L2: BY CLUB
B5: Name | C5: Club | D5: Sex | E5: Tennis Strength | F5: Badminton Strength | G5: Squash Strength | H5: TT Strength | L5: ="Tennis: " & COUNTA(L6:L101) -> Tennis: 1 | M5: ="Badminton: " & COUNTA(M6:M101) -> Badminton: 1 | N5: ="Squash: " & COUNTA(N6:N101) -> Squash: 1 | O5: ="Table Tennis: " & COUNTA(O6:O101) -> Table Tennis: 1 | P5: ="Other: " & COUNTA(P6:P101) -> Other: 1
B6: John Doe | C6: Tennis | D6: M | E6: 8 | F6: 5 | G6: 5 | H6: 2 | L6: =IFERROR(__xludf.DUMMYFUNCTION("FILTER(B3:B1000, C3:C1000 = ""Tennis"")"),"John Doe") -> John Doe | M6: =IFERROR(__xludf.DUMMYFUNCTION("FILTER(B3:B1000, C3:C1000 = ""Badminton"")"),"Bentley") -> Bentley | N6: =IFERROR(__xludf.DUMMYFUNCTION("FILTER(B3:B1000, C3:C1000 = ""Squash"")"),"Archie") -> Archie | O6: =IFERROR(__xludf.DUMMYFUNCTION("FILTER(B3:B1000, C3:C1000 = ""Table Tennis"")"),"#N/A") -> #N/A | P6: =IFERROR(__xludf.DUMMYFUNCTION("FILTER(B3:B1000, C3:C1000 = ""Other"")"),"Tina") -> Tina
B7: Archie | C7: Squash | D7: NA | E7: 5 | F7: 4 | G7: 2 | H7: 1
B8: Bentley | C8: Badminton | D8: F | E8: 7 | F8: 6 | G8: 4 | H8: 2
B9: Tina | C9: Other | D9: F | E9: 2 | F9: 3 | G9: 7 | H9: 7

Sheet Teams
B2: Teams that are determined on the day.
B4: Box A
B5: Team 1 | C5: T1P1 | D5: T1P2 | E5: T1P3 | F5: T1P4
B6: Team 2 | C6: T2P1 | D6: T2P2 | E6: T2P3 | F6: T2P4
B7: Team 3 | C7: T3P1 | D7: T3P2 | E7: T3P3 | F7: T3P4
B8: Team 4 | C8: T4P1 | D8: T4P2 | E8: T4P3 | F8: T4P4
B11: Box B
B12: Team 5 | C12: T5P1 | D12: T5P2 | E12: T5P3 | F12: T5P4
B13: Team 6 | C13: T6P1 | D13: T6P2 | E13: T6P3 | F13: T6P4
B14: Team 7 | C14: T7P1 | D14: T7P2 | E14: T7P3 | F14: T7P4
B15: Team 8 | C15: T8P1 | D15: T8P2 | E15: T8P3 | F15: T8P4
B18: Box C
B19: Team 9 | C19: T9P1 | D19: T9P2 | E19: T9P3 | F19: T9P4
B20: Team 10 | C20: T10P1 | D20: T10P2 | E20: T10P3 | F20: T10P4
B21: Team 11 | C21: T11P1 | D21: T11P2 | E21: T11P3 | F21: T11P4
B22: Team 12 | C22: T12P1 | D22: T12P2 | E22: T12P3 | F22: T12P4

Sheet Box_A
A2: BOX A | Z2: TOTAL SCORES
A5: =Teams!B5 -> Team 1 | C5: ="M1: " & Teams!B6 -> M1: Team 2 | D5: Tennis | E5: Badminton | F5: Squash | G5: TT | H5: Total | J5: ="M2: " & Teams!B7 -> M2: Team 3 | K5: Tennis | L5: Badminton | M5: Squash | N5: TT | O5: Total | Q5: ="M3: " & Teams!B8 -> M3: Team 4 | R5: Tennis | S5: Badminton | T5: Squash | U5: TT | V5: Total | AA5: Name: | AB5: Points:
C6: =Teams!C5 -> T1P1 | H6: =SUM(D6:G6) -> 0 | J6: =Teams!C5 -> T1P1 | O6: =SUM(K6:N6) -> 0 | Q6: =Teams!C5 -> T1P1 | V6: =SUM(R6:U6) -> 0 | Z6: =Teams!B5 -> Team 1 | AA6: =Teams!C5 -> T1P1 | AB6: =SUM(H6,O6,V6) -> 0
C7: =Teams!D5 -> T1P2 | H7: =SUM(D7:G7) -> 0 | J7: =Teams!D5 -> T1P2 | O7: =SUM(K7:N7) -> 0 | Q7: =Teams!D5 -> T1P2 | V7: =SUM(R7:U7) -> 0 | Z7: =SUM(AB6:AB9) -> 0 | AA7: =Teams!D5 -> T1P2 | AB7: =SUM(H7,O7,V7) -> 0
C8: =Teams!E5 -> T1P3 | H8: =SUM(D8:G8) -> 0 | J8: =Teams!E5 -> T1P3 | O8: =SUM(K8:N8) -> 0 | Q8: =Teams!E5 -> T1P3 | V8: =SUM(R8:U8) -> 0 | AA8: =Teams!E5 -> T1P3 | AB8: =SUM(H8,O8,V8) -> 0
C9: =Teams!F5 -> T1P4 | H9: =SUM(D9:G9) -> 0 | J9: =Teams!F5 -> T1P4 | O9: =SUM(K9:N9) -> 0 | Q9: =Teams!F5 -> T1P4 | V9: =SUM(R9:U9) -> 0 | AA9: =Teams!F5 -> T1P4 | AB9: =SUM(H9,O9,V9) -> 0
AA10: =Teams!M4
A11: =Teams!B6 -> Team 2 | C11: ="M1: " & Teams!B5 -> M1: Team 1 | D11: Tennis | E11: Badminton | F11: Squash | G11: TT | H11: Total | J11: ="M2: " & Teams!B8 -> M2: Team 4 | K11: Tennis | L11: Badminton | M11: Squash | N11: TT | O11: Total | Q11: ="M3: " & Teams!B7 -> M3: Team 3 | R11: Tennis | S11: Badminton | T11: Squash | U11: TT | V11: Total | Z11: =Teams!B6 -> Team 2 | AA11: =Teams!C6 -> T2P1 | AB11: =SUM(H12,O12,V12) -> 0
C12: =Teams!C6 -> T2P1 | H12: =SUM(D12:G12) -> 0 | J12: =Teams!C6 -> T2P1 | O12: =SUM(K12:N12) -> 0 | Q12: =Teams!C6 -> T2P1 | V12: =SUM(R12:U12) -> 0 | Z12: =SUM(AB11:AB14) -> 0 | AA12: =Teams!D6 -> T2P2 | AB12: =SUM(H13,O13,V13) -> 0
C13: =Teams!D6 -> T2P2 | H13: =SUM(D13:G13) -> 0 | J13: =Teams!D6 -> T2P2 | O13: =SUM(K13:N13) -> 0 | Q13: =Teams!D6 -> T2P2 | V13: =SUM(R13:U13) -> 0 | AA13: =Teams!E6 -> T2P3 | AB13: =SUM(H14,O14,V14) -> 0
C14: =Teams!E6 -> T2P3 | H14: =SUM(D14:G14) -> 0 | J14: =Teams!E6 -> T2P3 | O14: =SUM(K14:N14) -> 0 | Q14: =Teams!E6 -> T2P3 | V14: =SUM(R14:U14) -> 0 | AA14: =Teams!F6 -> T2P4 | AB14: =SUM(H15,O15,V15) -> 0
C15: =Teams!F6 -> T2P4 | H15: =SUM(D15:G15) -> 0 | J15: =Teams!F6 -> T2P4 | O15: =SUM(K15:N15) -> 0 | Q15: =Teams!F6 -> T2P4 | V15: =SUM(R15:U15) -> 0 | AA15: =Teams!N3
Z16: =Teams!B7 -> Team 3 | AA16: =Teams!C7 -> T3P1 | AB16: =SUM(H18,O18,V18) -> 0
A17: =Teams!B7 -> Team 3 | C17: ="M1: " & Teams!B8 -> M1: Team 4 | D17: Tennis | E17: Badminton | F17: Squash | G17: TT | H17: Total | J17: ="M2: " & Teams!B5 -> M2: Team 1 | K17: Tennis | L17: Badminton | M17: Squash | N17: TT | O17: Total | Q17: ="M3: " & Teams!B6 -> M3: Team 2 | R17: Tennis | S17: Badminton | T17: Squash | U17: TT | V17: Total | Z17: =SUM(AB16:AB19) -> 0 | AA17: =Teams!D7 -> T3P2 | AB17: =SUM(H19,O19,V19) -> 0
C18: =Teams!C7 -> T3P1 | H18: =SUM(D18:G18) -> 0 | J18: =Teams!C7 -> T3P1 | O18: =SUM(K18:N18) -> 0 | Q18: =Teams!C7 -> T3P1 | V18: =SUM(R18:U18) -> 0 | AA18: =Teams!E7 -> T3P3 | AB18: =SUM(H20,O20,V20) -> 0
C19: =Teams!D7 -> T3P2 | H19: =SUM(D19:G19) -> 0 | J19: =Teams!D7 -> T3P2 | O19: =SUM(K19:N19) -> 0 | Q19: =Teams!D7 -> T3P2 | V19: =SUM(R19:U19) -> 0 | AA19: =Teams!F7 -> T3P4 | AB19: =SUM(H21,O21,V21) -> 0
C20: =Teams!E7 -> T3P3 | H20: =SUM(D20:G20) -> 0 | J20: =Teams!E7 -> T3P3 | O20: =SUM(K20:N20) -> 0 | Q20: =Teams!E7 -> T3P3 | V20: =SUM(R20:U20) -> 0 | AA20: =Teams!O2
C21: =Teams!F7 -> T3P4 | H21: =SUM(D21:G21) -> 0 | J21: =Teams!F7 -> T3P4 | O21: =SUM(K21:N21) -> 0 | Q21: =Teams!F7 -> T3P4 | V21: =SUM(R21:U21) -> 0 | Z21: =Teams!B8 -> Team 4 | AA21: =Teams!C8 -> T4P1 | AB21: =SUM(H24,O24,V24) -> 0
Z22: =SUM(AB21:AB24) -> 0 | AA22: =Teams!D8 -> T4P2 | AB22: =SUM(H25,O25,V25) -> 0
A23: =Teams!B8 -> Team 4 | C23: ="M1: " & Teams!B7 -> M1: Team 3 | D23: Tennis | E23: Badminton | F23: Squash | G23: TT | H23: Total | J23: ="M2: " & Teams!B6 -> M2: Team 2 | K23: Tennis | L23: Badminton | M23: Squash | N23: TT | O23: Total | Q23: ="M3: " & Teams!B5 -> M3: Team 1 | R23: Tennis | S23: Badminton | T23: Squash | U23: TT | V23: Total | AA23: =Teams!E8 -> T4P3 | AB23: =SUM(H26,O26,V26) -> 0
C24: =Teams!C8 -> T4P1 | H24: =SUM(D24:G24) -> 0 | J24: =Teams!C8 -> T4P1 | O24: =SUM(K24:N24) -> 0 | Q24: =Teams!C8 -> T4P1 | V24: =SUM(R24:U24) -> 0 | AA24: =Teams!F8 -> T4P4 | AB24: =SUM(H27,O27,V27) -> 0
C25: =Teams!D8 -> T4P2 | H25: =SUM(D25:G25) -> 0 | J25: =Teams!D8 -> T4P2 | O25: =SUM(K25:N25) -> 0 | Q25: =Teams!D8 -> T4P2 | V25: =SUM(R25:U25) -> 0
C26: =Teams!E8 -> T4P3 | H26: =SUM(D26:G26) -> 0 | J26: =Teams!E8 -> T4P3 | O26: =SUM(K26:N26) -> 0 | Q26: =Teams!E8 -> T4P3 | V26: =SUM(R26:U26) -> 0
C27: =Teams!F8 -> T4P4 | H27: =SUM(D27:G27) -> 0 | J27: =Teams!F8 -> T4P4 | O27: =SUM(K27:N27) -> 0 | Q27: =Teams!F8 -> T4P4 | V27: =SUM(R27:U27) -> 0

Sheet Box_B
A2: BOX B | Z2: TOTAL SCORES
A5: =Teams!B12 -> Team 5 | C5: ="M1: " & Teams!B13 -> M1: Team 6 | D5: Tennis | E5: Badminton | F5: Squash | G5: TT | H5: Total | J5: ="M2: " & Teams!B14 -> M2: Team 7 | K5: Tennis | L5: Badminton | M5: Squash | N5: TT | O5: Total | Q5: ="M3: " & Teams!B15 -> M3: Team 8 | R5: Tennis | S5: Badminton | T5: Squash | U5: TT | V5: Total | AA5: Name: | AB5: Points:
C6: =Teams!C12 -> T5P1 | H6: =SUM(D6:G6) -> 0 | J6: =Teams!C12 -> T5P1 | O6: =SUM(K6:N6) -> 0 | Q6: =Teams!C12 -> T5P1 | V6: =SUM(R6:U6) -> 0 | Z6: =Teams!B12 -> Team 5 | AA6: =Teams!C12 -> T5P1 | AB6: =SUM(H6,O6,V6) -> 0
C7: =Teams!D12 -> T5P2 | H7: =SUM(D7:G7) -> 0 | J7: =Teams!D12 -> T5P2 | O7: =SUM(K7:N7) -> 0 | Q7: =Teams!D12 -> T5P2 | V7: =SUM(R7:U7) -> 0 | Z7: =SUM(AB6:AB9) -> 0 | AA7: =Teams!D12 -> T5P2 | AB7: =SUM(H7,O7,V7) -> 0
C8: =Teams!E12 -> T5P3 | H8: =SUM(D8:G8) -> 0 | J8: =Teams!E12 -> T5P3 | O8: =SUM(K8:N8) -> 0 | Q8: =Teams!E12 -> T5P3 | V8: =SUM(R8:U8) -> 0 | AA8: =Teams!E12 -> T5P3 | AB8: =SUM(H8,O8,V8) -> 0
C9: =Teams!F12 -> T5P4 | H9: =SUM(D9:G9) -> 0 | J9: =Teams!F12 -> T5P4 | O9: =SUM(K9:N9) -> 0 | Q9: =Teams!F12 -> T5P4 | V9: =SUM(R9:U9) -> 0 | AA9: =Teams!F12 -> T5P4 | AB9: =SUM(H9,O9,V9) -> 0
A11: =Teams!B13 -> Team 6 | C11: ="M1: " & Teams!B12 -> M1: Team 5 | D11: Tennis | E11: Badminton | F11: Squash | G11: TT | H11: Total | J11: ="M2: " & Teams!B15 -> M2: Team 8 | K11: Tennis | L11: Badminton | M11: Squash | N11: TT | O11: Total | Q11: ="M3: " & Teams!B14 -> M3: Team 7 | R11: Tennis | S11: Badminton | T11: Squash | U11: TT | V11: Total | Z11: =Teams!B13 -> Team 6 | AA11: =Teams!C13 -> T6P1 | AB11: =SUM(H12,O12,V12) -> 0
C12: =Teams!C13 -> T6P1 | H12: =SUM(D12:G12) -> 0 | J12: =Teams!C13 -> T6P1 | O12: =SUM(K12:N12) -> 0 | Q12: =Teams!C13 -> T6P1 | V12: =SUM(R12:U12) -> 0 | Z12: =SUM(AB11:AB14) -> 0 | AA12: =Teams!D13 -> T6P2 | AB12: =SUM(H13,O13,V13) -> 0
C13: =Teams!D13 -> T6P2 | H13: =SUM(D13:G13) -> 0 | J13: =Teams!D13 -> T6P2 | O13: =SUM(K13:N13) -> 0 | Q13: =Teams!D13 -> T6P2 | V13: =SUM(R13:U13) -> 0 | AA13: =Teams!E13 -> T6P3 | AB13: =SUM(H14,O14,V14) -> 0
C14: =Teams!E13 -> T6P3 | H14: =SUM(D14:G14) -> 0 | J14: =Teams!E13 -> T6P3 | O14: =SUM(K14:N14) -> 0 | Q14: =Teams!E13 -> T6P3 | V14: =SUM(R14:U14) -> 0 | AA14: =Teams!F13 -> T6P4 | AB14: =SUM(H15,O15,V15) -> 0
C15: =Teams!F13 -> T6P4 | H15: =SUM(D15:G15) -> 0 | J15: =Teams!F13 -> T6P4 | O15: =SUM(K15:N15) -> 0 | Q15: =Teams!F13 -> T6P4 | V15: =SUM(R15:U15) -> 0
Z16: =Teams!B14 -> Team 7 | AA16: =Teams!C14 -> T7P1 | AB16: =SUM(H18,O18,V18) -> 0
A17: =Teams!B14 -> Team 7 | C17: ="M1: " & Teams!B15 -> M1: Team 8 | D17: Tennis | E17: Badminton | F17: Squash | G17: TT | H17: Total | J17: ="M2: " & Teams!B12 -> M2: Team 5 | K17: Tennis | L17: Badminton | M17: Squash | N17: TT | O17: Total | Q17: ="M3: " & Teams!B13 -> M3: Team 6 | R17: Tennis | S17: Badminton | T17: Squash | U17: TT | V17: Total | Z17: =SUM(AB16:AB19) -> 0 | AA17: =Teams!D14 -> T7P2 | AB17: =SUM(H19,O19,V19) -> 0
C18: =Teams!C14 -> T7P1 | H18: =SUM(D18:G18) -> 0 | J18: =Teams!C14 -> T7P1 | O18: =SUM(K18:N18) -> 0 | Q18: =Teams!C14 -> T7P1 | V18: =SUM(R18:U18) -> 0 | AA18: =Teams!E14 -> T7P3 | AB18: =SUM(H20,O20,V20) -> 0
C19: =Teams!D14 -> T7P2 | H19: =SUM(D19:G19) -> 0 | J19: =Teams!D14 -> T7P2 | O19: =SUM(K19:N19) -> 0 | Q19: =Teams!D14 -> T7P2 | V19: =SUM(R19:U19) -> 0 | AA19: =Teams!F14 -> T7P4 | AB19: =SUM(H21,O21,V21) -> 0
C20: =Teams!E14 -> T7P3 | H20: =SUM(D20:G20) -> 0 | J20: =Teams!E14 -> T7P3 | O20: =SUM(K20:N20) -> 0 | Q20: =Teams!E14 -> T7P3 | V20: =SUM(R20:U20) -> 0
C21: =Teams!F14 -> T7P4 | H21: =SUM(D21:G21) -> 0 | J21: =Teams!F14 -> T7P4 | O21: =SUM(K21:N21) -> 0 | Q21: =Teams!F14 -> T7P4 | V21: =SUM(R21:U21) -> 0 | Z21: =Teams!B15 -> Team 8 | AA21: =Teams!C15 -> T8P1 | AB21: =SUM(H24,O24,V24) -> 0
Z22: =SUM(AB21:AB24) -> 0 | AA22: =Teams!D15 -> T8P2 | AB22: =SUM(H25,O25,V25) -> 0
A23: =Teams!B15 -> Team 8 | C23: ="M1: " & Teams!B14 -> M1: Team 7 | D23: Tennis | E23: Badminton | F23: Squash | G23: TT | H23: Total | J23: ="M2: " & Teams!B13 -> M2: Team 6 | K23: Tennis | L23: Badminton | M23: Squash | N23: TT | O23: Total | Q23: ="M3: " & Teams!B12 -> M3: Team 5 | R23: Tennis | S23: Badminton | T23: Squash | U23: TT | V23: Total | AA23: =Teams!E15 -> T8P3 | AB23: =SUM(H26,O26,V26) -> 0
C24: =Teams!C15 -> T8P1 | H24: =SUM(D24:G24) -> 0 | J24: =Teams!C15 -> T8P1 | O24: =SUM(K24:N24) -> 0 | Q24: =Teams!C15 -> T8P1 | V24: =SUM(R24:U24) -> 0 | AA24: =Teams!F15 -> T8P4 | AB24: =SUM(H27,O27,V27) -> 0
C25: =Teams!D15 -> T8P2 | H25: =SUM(D25:G25) -> 0 | J25: =Teams!D15 -> T8P2 | O25: =SUM(K25:N25) -> 0 | Q25: =Teams!D15 -> T8P2 | V25: =SUM(R25:U25) -> 0
C26: =Teams!E15 -> T8P3 | H26: =SUM(D26:G26) -> 0 | J26: =Teams!E15 -> T8P3 | O26: =SUM(K26:N26) -> 0 | Q26: =Teams!E15 -> T8P3 | V26: =SUM(R26:U26) -> 0
C27: =Teams!F15 -> T8P4 | H27: =SUM(D27:G27) -> 0 | J27: =Teams!F15 -> T8P4 | O27: =SUM(K27:N27) -> 0 | Q27: =Teams!F15 -> T8P4 | V27: =SUM(R27:U27) -> 0

Sheet Box_C
A2: BOX C | Z2: TOTAL SCORES
A5: =Teams!B19 -> Team 9 | C5: ="M1: " & Teams!B20 -> M1: Team 10 | D5: Tennis | E5: Badminton | F5: Squash | G5: TT | H5: Total | J5: ="M2: " & Teams!B21 -> M2: Team 11 | K5: Tennis | L5: Badminton | M5: Squash | N5: TT | O5: Total | Q5: ="M3: " & Teams!B22 -> M3: Team 12 | R5: Tennis | S5: Badminton | T5: Squash | U5: TT | V5: Total | AA5: Name: | AB5: Points:
C6: =Teams!C19 -> T9P1 | H6: =SUM(D6:G6) -> 0 | J6: =Teams!C19 -> T9P1 | O6: =SUM(K6:N6) -> 0 | Q6: =Teams!C19 -> T9P1 | V6: =SUM(R6:U6) -> 0 | Z6: =Teams!B19 -> Team 9 | AA6: =Teams!C19 -> T9P1 | AB6: =SUM(H6,O6,V6) -> 0
C7: =Teams!D19 -> T9P2 | H7: =SUM(D7:G7) -> 0 | J7: =Teams!D19 -> T9P2 | O7: =SUM(K7:N7) -> 0 | Q7: =Teams!D19 -> T9P2 | V7: =SUM(R7:U7) -> 0 | Z7: =SUM(AB6:AB9) -> 0 | AA7: =Teams!D19 -> T9P2 | AB7: =SUM(H7,O7,V7) -> 0
C8: =Teams!E19 -> T9P3 | H8: =SUM(D8:G8) -> 0 | J8: =Teams!E19 -> T9P3 | O8: =SUM(K8:N8) -> 0 | Q8: =Teams!E19 -> T9P3 | V8: =SUM(R8:U8) -> 0 | AA8: =Teams!E19 -> T9P3 | AB8: =SUM(H8,O8,V8) -> 0
C9: =Teams!F19 -> T9P4 | H9: =SUM(D9:G9) -> 0 | J9: =Teams!F19 -> T9P4 | O9: =SUM(K9:N9) -> 0 | Q9: =Teams!F19 -> T9P4 | V9: =SUM(R9:U9) -> 0 | AA9: =Teams!F19 -> T9P4 | AB9: =SUM(H9,O9,V9) -> 0
A11: =Teams!B20 -> Team 10 | C11: ="M1: " & Teams!B19 -> M1: Team 9 | D11: Tennis | E11: Badminton | F11: Squash | G11: TT | H11: Total | J11: ="M2: " & Teams!B22 -> M2: Team 12 | K11: Tennis | L11: Badminton | M11: Squash | N11: TT | O11: Total | Q11: ="M3: " & Teams!B21 -> M3: Team 11 | R11: Tennis | S11: Badminton | T11: Squash | U11: TT | V11: Total | Z11: =Teams!B20 -> Team 10 | AA11: =Teams!C20 -> T10P1 | AB11: =SUM(H12,O12,V12) -> 0
C12: =Teams!C20 -> T10P1 | H12: =SUM(D12:G12) -> 0 | J12: =Teams!C20 -> T10P1 | O12: =SUM(K12:N12) -> 0 | Q12: =Teams!C20 -> T10P1 | V12: =SUM(R12:U12) -> 0 | Z12: =SUM(AB11:AB14) -> 0 | AA12: =Teams!D20 -> T10P2 | AB12: =SUM(H13,O13,V13) -> 0
C13: =Teams!D20 -> T10P2 | H13: =SUM(D13:G13) -> 0 | J13: =Teams!D20 -> T10P2 | O13: =SUM(K13:N13) -> 0 | Q13: =Teams!D20 -> T10P2 | V13: =SUM(R13:U13) -> 0 | AA13: =Teams!E20 -> T10P3 | AB13: =SUM(H14,O14,V14) -> 0
C14: =Teams!E20 -> T10P3 | H14: =SUM(D14:G14) -> 0 | J14: =Teams!E20 -> T10P3 | O14: =SUM(K14:N14) -> 0 | Q14: =Teams!E20 -> T10P3 | V14: =SUM(R14:U14) -> 0 | AA14: =Teams!F20 -> T10P4 | AB14: =SUM(H15,O15,V15) -> 0
C15: =Teams!F20 -> T10P4 | H15: =SUM(D15:G15) -> 0 | J15: =Teams!F20 -> T10P4 | O15: =SUM(K15:N15) -> 0 | Q15: =Teams!F20 -> T10P4 | V15: =SUM(R15:U15) -> 0
Z16: =Teams!B21 -> Team 11 | AA16: =Teams!C21 -> T11P1 | AB16: =SUM(H18,O18,V18) -> 0
A17: =Teams!B21 -> Team 11 | C17: ="M1: " & Teams!B22 -> M1: Team 12 | D17: Tennis | E17: Badminton | F17: Squash | G17: TT | H17: Total | J17: ="M2: " & Teams!B19 -> M2: Team 9 | K17: Tennis | L17: Badminton | M17: Squash | N17: TT | O17: Total | Q17: ="M3: " & Teams!B20 -> M3: Team 10 | R17: Tennis | S17: Badminton | T17: Squash | U17: TT | V17: Total | Z17: =SUM(AB16:AB19) -> 0 | AA17: =Teams!D21 -> T11P2 | AB17: =SUM(H19,O19,V19) -> 0
C18: =Teams!C21 -> T11P1 | H18: =SUM(D18:G18) -> 0 | J18: =Teams!C21 -> T11P1 | O18: =SUM(K18:N18) -> 0 | Q18: =Teams!C21 -> T11P1 | V18: =SUM(R18:U18) -> 0 | AA18: =Teams!E21 -> T11P3 | AB18: =SUM(H20,O20,V20) -> 0
C19: =Teams!D21 -> T11P2 | H19: =SUM(D19:G19) -> 0 | J19: =Teams!D21 -> T11P2 | O19: =SUM(K19:N19) -> 0 | Q19: =Teams!D21 -> T11P2 | V19: =SUM(R19:U19) -> 0 | AA19: =Teams!F21 -> T11P4 | AB19: =SUM(H21,O21,V21) -> 0
C20: =Teams!E21 -> T11P3 | H20: =SUM(D20:G20) -> 0 | J20: =Teams!E21 -> T11P3 | O20: =SUM(K20:N20) -> 0 | Q20: =Teams!E21 -> T11P3 | V20: =SUM(R20:U20) -> 0
C21: =Teams!F21 -> T11P4 | H21: =SUM(D21:G21) -> 0 | J21: =Teams!F21 -> T11P4 | O21: =SUM(K21:N21) -> 0 | Q21: =Teams!F21 -> T11P4 | V21: =SUM(R21:U21) -> 0 | Z21: =Teams!B22 -> Team 12 | AA21: =Teams!C22 -> T12P1 | AB21: =SUM(H24,O24,V24) -> 0
Z22: =SUM(AB21:AB24) -> 0 | AA22: =Teams!D22 -> T12P2 | AB22: =SUM(H25,O25,V25) -> 0
A23: =Teams!B22 -> Team 12 | C23: ="M1: " & Teams!B21 -> M1: Team 11 | D23: Tennis | E23: Badminton | F23: Squash | G23: TT | H23: Total | J23: ="M2: " & Teams!B20 -> M2: Team 10 | K23: Tennis | L23: Badminton | M23: Squash | N23: TT | O23: Total | Q23: ="M3: " & Teams!B19 -> M3: Team 9 | R23: Tennis | S23: Badminton | T23: Squash | U23: TT | V23: Total | AA23: =Teams!E22 -> T12P3 | AB23: =SUM(H26,O26,V26) -> 0
C24: =Teams!C22 -> T12P1 | H24: =SUM(D24:G24) -> 0 | J24: =Teams!C22 -> T12P1 | O24: =SUM(K24:N24) -> 0 | Q24: =Teams!C22 -> T12P1 | V24: =SUM(R24:U24) -> 0 | AA24: =Teams!F22 -> T12P4 | AB24: =SUM(H27,O27,V27) -> 0
C25: =Teams!D22 -> T12P2 | H25: =SUM(D25:G25) -> 0 | J25: =Teams!D22 -> T12P2 | O25: =SUM(K25:N25) -> 0 | Q25: =Teams!D22 -> T12P2 | V25: =SUM(R25:U25) -> 0
C26: =Teams!E22 -> T12P3 | H26: =SUM(D26:G26) -> 0 | J26: =Teams!E22 -> T12P3 | O26: =SUM(K26:N26) -> 0 | Q26: =Teams!E22 -> T12P3 | V26: =SUM(R26:U26) -> 0
C27: =Teams!F22 -> T12P4 | H27: =SUM(D27:G27) -> 0 | J27: =Teams!F22 -> T12P4 | O27: =SUM(K27:N27) -> 0 | Q27: =Teams!F22 -> T12P4 | V27: =SUM(R27:U27) -> 0

Sheet Final Scores
B2: UNSORTED - scroll right for final, sorted results! | V2: FINAL RESULTS - TEAMS | AB2: FINAL RESULTS - PLAYERS | AH2: FINAL RESULTS - CLUBS
B4: Unsorted Teams | E4: Unsorted Players | I4: Unsorted Clubs
B5: Team | C5: Points | E5: Player | F5: Club | G5: Points | I5: ="Tennis: " & SUM(J6:J40) -> #N/A | K5: ="Badminton: " & SUM(L6:L40) -> #N/A | M5: ="Squash: " & SUM(N6:N40) -> #N/A | O5: ="Table Tennis: " & SUM(P6:P40) -> #N/A | Q5: ="Other: " & SUM(R6:R40) -> Other: 0 | V5: {=SORT(B6:B17, C6:C17, false)} -> Team 1 | W5: {=SORT(C6:C17, C6:C17, false)} -> 0 | X5: 🥇Prize: ??? | AB5: =IFERROR(__xludf.DUMMYFUNCTION("SORTN(E6:E200, 5, 1, G6:G200, false)"),"T1P1") -> T1P1 | AC5: =IFERROR(__xludf.DUMMYFUNCTION("SORTN(G6:G200, 5, 1, G6:G200, false)"),0.0) -> 0 | AD5: 🥇Prize: ??? | AH5: {=SORT(I47:I51, J47:J51, false)} -> Tennis | AI5: {=SORT(J47:J51, J47:J51, false)} -> #N/A | AJ5: 🥇Prize: ???
B6: =Teams!B5 -> Team 1 | C6: =Box_A!Z7 -> 0 | E6: =Teams!C5 -> T1P1 | F6: {=IFERROR(XLOOKUP(E6, SignupNames, SignupClubs), "Not Found")} -> Not Found | G6: =Box_A!AB6 -> 0 | I6: =IFERROR(__xludf.DUMMYFUNCTION("FILTER(E6:E200, F6:F200 = ""Tennis"")"),"#N/A") -> #N/A | J6: =IFERROR(__xludf.DUMMYFUNCTION("FILTER(G6:G200, F6:F200 = ""Tennis"")"),"#N/A") -> #N/A | K6: =IFERROR(__xludf.DUMMYFUNCTION("FILTER(E6:E200, F6:F200 = ""Badminton"")"),"#N/A") -> #N/A | L6: =IFERROR(__xludf.DUMMYFUNCTION("FILTER(G6:G200, F6:F200 = ""Badminton"")"),"#N/A") -> #N/A | M6: =IFERROR(__xludf.DUMMYFUNCTION("FILTER(E6:E200, F6:F200 = ""Squash"")"),"#N/A") -> #N/A | N6: =IFERROR(__xludf.DUMMYFUNCTION("FILTER(G6:G200, F6:F200 = ""Squash"")"),"#N/A") -> #N/A | O6: =IFERROR(__xludf.DUMMYFUNCTION("FILTER(E6:E200, F6:F200 = ""Table Tennis"")"),"#N/A") -> #N/A | P6: =IFERROR(__xludf.DUMMYFUNCTION("FILTER(G6:G200, F6:F200 = ""Table Tennis"")"),"#N/A") -> #N/A | V6: Team 2 | W6: 0 | X6: 🥈Prize: ??? | AB6: =IFERROR(__xludf.DUMMYFUNCTION("""COMPUTED_VALUE"""),"T1P2") -> T1P2 | AC6: =IFERROR(__xludf.DUMMYFUNCTION("""COMPUTED_VALUE"""),0.0) -> 0 | AD6: 🥈Prize: ??? | AH6: Badminton | AI6: #N/A | AJ6: 🥈Prize: ???
B7: =Teams!B6 -> Team 2 | C7: =Box_A!Z12 -> 0 | E7: =Teams!D5 -> T1P2 | F7: {=IFERROR(XLOOKUP(E7, SignupNames, SignupClubs), "Not Found")} -> Not Found | G7: =Box_A!AB7 -> 0 | V7: Team 3 | W7: 0 | X7: 🥉Prize: ??? | AB7: =IFERROR(__xludf.DUMMYFUNCTION("""COMPUTED_VALUE"""),"T1P3") -> T1P3 | AC7: =IFERROR(__xludf.DUMMYFUNCTION("""COMPUTED_VALUE"""),0.0) -> 0 | AD7: 🥉Prize: ??? | AH7: Squash | AI7: #N/A | AJ7: 🥉Prize: ???
B8: =Teams!B7 -> Team 3 | C8: =Box_A!Z17 -> 0 | E8: =Teams!E5 -> T1P3 | F8: {=IFERROR(XLOOKUP(E8, SignupNames, SignupClubs), "Not Found")} -> Not Found | G8: =Box_A!AB8 -> 0 | V8: Team 4 | W8: 0 | AB8: =IFERROR(__xludf.DUMMYFUNCTION("""COMPUTED_VALUE"""),"T1P4") -> T1P4 | AC8: =IFERROR(__xludf.DUMMYFUNCTION("""COMPUTED_VALUE"""),0.0) -> 0 | AH8: Table Tennis | AI8: #N/A
B9: =Teams!B8 -> Team 4 | C9: =Box_A!Z22 -> 0 | E9: =Teams!F5 -> T1P4 | F9: {=IFERROR(XLOOKUP(E9, SignupNames, SignupClubs), "Not Found")} -> Not Found | G9: =Box_A!AB9 -> 0 | V9: Team 5 | W9: 0 | AB9: =IFERROR(__xludf.DUMMYFUNCTION("""COMPUTED_VALUE"""),"T2P1") -> T2P1 | AC9: =IFERROR(__xludf.DUMMYFUNCTION("""COMPUTED_VALUE"""),0.0) -> 0 | AH9: Other | AI9: 0
B10: =Teams!B12 -> Team 5 | C10: =Box_B!Z7 -> 0 | E10: =Teams!C6 -> T2P1 | F10: {=IFERROR(XLOOKUP(E10, SignupNames, SignupClubs), "Not Found")} -> Not Found | G10: =Box_A!AB11 -> 0 | V10: Team 6 | W10: 0 | AB10: =IFERROR(__xludf.DUMMYFUNCTION("""COMPUTED_VALUE"""),"T2P2") -> T2P2 | AC10: =IFERROR(__xludf.DUMMYFUNCTION("""COMPUTED_VALUE"""),0.0) -> 0
B11: =Teams!B13 -> Team 6 | C11: =Box_B!Z12 -> 0 | E11: =Teams!D6 -> T2P2 | F11: {=IFERROR(XLOOKUP(E11, SignupNames, SignupClubs), "Not Found")} -> Not Found | G11: =Box_A!AB12 -> 0 | V11: Team 7 | W11: 0 | AB11: =IFERROR(__xludf.DUMMYFUNCTION("""COMPUTED_VALUE"""),"T2P3") -> T2P3 | AC11: =IFERROR(__xludf.DUMMYFUNCTION("""COMPUTED_VALUE"""),0.0) -> 0
B12: =Teams!B14 -> Team 7 | C12: =Box_B!Z17 -> 0 | E12: =Teams!E6 -> T2P3 | F12: {=IFERROR(XLOOKUP(E12, SignupNames, SignupClubs), "Not Found")} -> Not Found | G12: =Box_A!AB13 -> 0 | V12: Team 8 | W12: 0 | AB12: =IFERROR(__xludf.DUMMYFUNCTION("""COMPUTED_VALUE"""),"T2P4") -> T2P4 | AC12: =IFERROR(__xludf.DUMMYFUNCTION("""COMPUTED_VALUE"""),0.0) -> 0
B13: =Teams!B15 -> Team 8 | C13: =Box_B!Z22 -> 0 | E13: =Teams!F6 -> T2P4 | F13: {=IFERROR(XLOOKUP(E13, SignupNames, SignupClubs), "Not Found")} -> Not Found | G13: =Box_A!AB14 -> 0 | V13: Team 9 | W13: 0 | AB13: =IFERROR(__xludf.DUMMYFUNCTION("""COMPUTED_VALUE"""),"T3P1") -> T3P1 | AC13: =IFERROR(__xludf.DUMMYFUNCTION("""COMPUTED_VALUE"""),0.0) -> 0
B14: =Teams!B19 -> Team 9 | C14: =Box_C!Z7 -> 0 | E14: =Teams!C7 -> T3P1 | F14: {=IFERROR(XLOOKUP(E14, SignupNames, SignupClubs), "Not Found")} -> Not Found | G14: =Box_A!AB16 -> 0 | V14: Team 10 | W14: 0 | AB14: =IFERROR(__xludf.DUMMYFUNCTION("""COMPUTED_VALUE"""),"T3P2") -> T3P2 | AC14: =IFERROR(__xludf.DUMMYFUNCTION("""COMPUTED_VALUE"""),0.0) -> 0
B15: =Teams!B20 -> Team 10 | C15: =Box_C!Z12 -> 0 | E15: =Teams!D7 -> T3P2 | F15: {=IFERROR(XLOOKUP(E15, SignupNames, SignupClubs), "Not Found")} -> Not Found | G15: =Box_A!AB17 -> 0 | V15: Team 11 | W15: 0 | AB15: =IFERROR(__xludf.DUMMYFUNCTION("""COMPUTED_VALUE"""),"T3P3") -> T3P3 | AC15: =IFERROR(__xludf.DUMMYFUNCTION("""COMPUTED_VALUE"""),0.0) -> 0
B16: =Teams!B21 -> Team 11 | C16: =Box_C!Z17 -> 0 | E16: =Teams!E7 -> T3P3 | F16: {=IFERROR(XLOOKUP(E16, SignupNames, SignupClubs), "Not Found")} -> Not Found | G16: =Box_A!AB18 -> 0 | V16: Team 12 | W16: 0 | AB16: =IFERROR(__xludf.DUMMYFUNCTION("""COMPUTED_VALUE"""),"T3P4") -> T3P4 | AC16: =IFERROR(__xludf.DUMMYFUNCTION("""COMPUTED_VALUE"""),0.0) -> 0
B17: =Teams!B22 -> Team 12 | C17: =Box_C!Z22 -> 0 | E17: =Teams!F7 -> T3P4 | F17: {=IFERROR(XLOOKUP(E17, SignupNames, SignupClubs), "Not Found")} -> Not Found | G17: =Box_A!AB19 -> 0 | AB17: =IFERROR(__xludf.DUMMYFUNCTION("""COMPUTED_VALUE"""),"T4P1") -> T4P1 | AC17: =IFERROR(__xludf.DUMMYFUNCTION("""COMPUTED_VALUE"""),0.0) -> 0
E18: =Teams!C8 -> T4P1 | F18: {=IFERROR(XLOOKUP(E18, SignupNames, SignupClubs), "Not Found")} -> Not Found | G18: =Box_A!AB21 -> 0 | AB18: =IFERROR(__xludf.DUMMYFUNCTION("""COMPUTED_VALUE"""),"T4P2") -> T4P2 | AC18: =IFERROR(__xludf.DUMMYFUNCTION("""COMPUTED_VALUE"""),0.0) -> 0
E19: =Teams!D8 -> T4P2 | F19: {=IFERROR(XLOOKUP(E19, SignupNames, SignupClubs), "Not Found")} -> Not Found | G19: =Box_A!AB22 -> 0 | AB19: =IFERROR(__xludf.DUMMYFUNCTION("""COMPUTED_VALUE"""),"T4P3") -> T4P3 | AC19: =IFERROR(__xludf.DUMMYFUNCTION("""COMPUTED_VALUE"""),0.0) -> 0
E20: =Teams!E8 -> T4P3 | F20: {=IFERROR(XLOOKUP(E20, SignupNames, SignupClubs), "Not Found")} -> Not Found | G20: =Box_A!AB23 -> 0 | AB20: =IFERROR(__xludf.DUMMYFUNCTION("""COMPUTED_VALUE"""),"T4P4") -> T4P4 | AC20: =IFERROR(__xludf.DUMMYFUNCTION("""COMPUTED_VALUE"""),0.0) -> 0
E21: =Teams!F8 -> T4P4 | F21: {=IFERROR(XLOOKUP(E21, SignupNames, SignupClubs), "Not Found")} -> Not Found | G21: =Box_A!AB24 -> 0 | AB21: =IFERROR(__xludf.DUMMYFUNCTION("""COMPUTED_VALUE"""),"T5P1") -> T5P1 | AC21: =IFERROR(__xludf.DUMMYFUNCTION("""COMPUTED_VALUE"""),0.0) -> 0
E22: =Teams!C12 -> T5P1 | F22: {=IFERROR(XLOOKUP(E22, SignupNames, SignupClubs), "Not Found")} -> Not Found | G22: =Box_B!AB6 -> 0 | AB22: =IFERROR(__xludf.DUMMYFUNCTION("""COMPUTED_VALUE"""),"T5P2") -> T5P2 | AC22: =IFERROR(__xludf.DUMMYFUNCTION("""COMPUTED_VALUE"""),0.0) -> 0
E23: =Teams!D12 -> T5P2 | F23: {=IFERROR(XLOOKUP(E23, SignupNames, SignupClubs), "Not Found")} -> Not Found | G23: =Box_B!AB7 -> 0 | AB23: =IFERROR(__xludf.DUMMYFUNCTION("""COMPUTED_VALUE"""),"T5P3") -> T5P3 | AC23: =IFERROR(__xludf.DUMMYFUNCTION("""COMPUTED_VALUE"""),0.0) -> 0
E24: =Teams!E12 -> T5P3 | F24: {=IFERROR(XLOOKUP(E24, SignupNames, SignupClubs), "Not Found")} -> Not Found | G24: =Box_B!AB8 -> 0 | AB24: =IFERROR(__xludf.DUMMYFUNCTION("""COMPUTED_VALUE"""),"T5P4") -> T5P4 | AC24: =IFERROR(__xludf.DUMMYFUNCTION("""COMPUTED_VALUE"""),0.0) -> 0
E25: =Teams!F12 -> T5P4 | F25: {=IFERROR(XLOOKUP(E25, SignupNames, SignupClubs), "Not Found")} -> Not Found | G25: =Box_B!AB9 -> 0 | AB25: =IFERROR(__xludf.DUMMYFUNCTION("""COMPUTED_VALUE"""),"T6P1") -> T6P1 | AC25: =IFERROR(__xludf.DUMMYFUNCTION("""COMPUTED_VALUE"""),0.0) -> 0
E26: =Teams!C13 -> T6P1 | F26: {=IFERROR(XLOOKUP(E26, SignupNames, SignupClubs), "Not Found")} -> Not Found | G26: =Box_B!AB11 -> 0 | AB26: =IFERROR(__xludf.DUMMYFUNCTION("""COMPUTED_VALUE"""),"T6P2") -> T6P2 | AC26: =IFERROR(__xludf.DUMMYFUNCTION("""COMPUTED_VALUE"""),0.0) -> 0
E27: =Teams!D13 -> T6P2 | F27: {=IFERROR(XLOOKUP(E27, SignupNames, SignupClubs), "Not Found")} -> Not Found | G27: =Box_B!AB12 -> 0 | AB27: =IFERROR(__xludf.DUMMYFUNCTION("""COMPUTED_VALUE"""),"T6P3") -> T6P3 | AC27: =IFERROR(__xludf.DUMMYFUNCTION("""COMPUTED_VALUE"""),0.0) -> 0
E28: =Teams!E13 -> T6P3 | F28: {=IFERROR(XLOOKUP(E28, SignupNames, SignupClubs), "Not Found")} -> Not Found | G28: =Box_B!AB13 -> 0 | AB28: =IFERROR(__xludf.DUMMYFUNCTION("""COMPUTED_VALUE"""),"T6P4") -> T6P4 | AC28: =IFERROR(__xludf.DUMMYFUNCTION("""COMPUTED_VALUE"""),0.0) -> 0
E29: =Teams!F13 -> T6P4 | F29: {=IFERROR(XLOOKUP(E29, SignupNames, SignupClubs), "Not Found")} -> Not Found | G29: =Box_B!AB14 -> 0 | AB29: =IFERROR(__xludf.DUMMYFUNCTION("""COMPUTED_VALUE"""),"T7P1") -> T7P1 | AC29: =IFERROR(__xludf.DUMMYFUNCTION("""COMPUTED_VALUE"""),0.0) -> 0
E30: =Teams!C14 -> T7P1 | F30: {=IFERROR(XLOOKUP(E30, SignupNames, SignupClubs), "Not Found")} -> Not Found | G30: =Box_B!AB16 -> 0 | AB30: =IFERROR(__xludf.DUMMYFUNCTION("""COMPUTED_VALUE"""),"T7P2") -> T7P2 | AC30: =IFERROR(__xludf.DUMMYFUNCTION("""COMPUTED_VALUE"""),0.0) -> 0
E31: =Teams!D14 -> T7P2 | F31: {=IFERROR(XLOOKUP(E31, SignupNames, SignupClubs), "Not Found")} -> Not Found | G31: =Box_B!AB17 -> 0 | AB31: =IFERROR(__xludf.DUMMYFUNCTION("""COMPUTED_VALUE"""),"T7P3") -> T7P3 | AC31: =IFERROR(__xludf.DUMMYFUNCTION("""COMPUTED_VALUE"""),0.0) -> 0
E32: =Teams!E14 -> T7P3 | F32: {=IFERROR(XLOOKUP(E32, SignupNames, SignupClubs), "Not Found")} -> Not Found | G32: =Box_B!AB18 -> 0 | AB32: =IFERROR(__xludf.DUMMYFUNCTION("""COMPUTED_VALUE"""),"T7P4") -> T7P4 | AC32: =IFERROR(__xludf.DUMMYFUNCTION("""COMPUTED_VALUE"""),0.0) -> 0
E33: =Teams!F14 -> T7P4 | F33: {=IFERROR(XLOOKUP(E33, SignupNames, SignupClubs), "Not Found")} -> Not Found | G33: =Box_B!AB19 -> 0 | AB33: =IFERROR(__xludf.DUMMYFUNCTION("""COMPUTED_VALUE"""),"T8P1") -> T8P1 | AC33: =IFERROR(__xludf.DUMMYFUNCTION("""COMPUTED_VALUE"""),0.0) -> 0
E34: =Teams!C15 -> T8P1 | F34: {=IFERROR(XLOOKUP(E34, SignupNames, SignupClubs), "Not Found")} -> Not Found | G34: =Box_B!AB21 -> 0 | AB34: =IFERROR(__xludf.DUMMYFUNCTION("""COMPUTED_VALUE"""),"T8P2") -> T8P2 | AC34: =IFERROR(__xludf.DUMMYFUNCTION("""COMPUTED_VALUE"""),0.0) -> 0
E35: =Teams!D15 -> T8P2 | F35: {=IFERROR(XLOOKUP(E35, SignupNames, SignupClubs), "Not Found")} -> Not Found | G35: =Box_B!AB22 -> 0 | AB35: =IFERROR(__xludf.DUMMYFUNCTION("""COMPUTED_VALUE"""),"T8P3") -> T8P3 | AC35: =IFERROR(__xludf.DUMMYFUNCTION("""COMPUTED_VALUE"""),0.0) -> 0
E36: =Teams!E15 -> T8P3 | F36: {=IFERROR(XLOOKUP(E36, SignupNames, SignupClubs), "Not Found")} -> Not Found | G36: =Box_B!AB23 -> 0 | AB36: =IFERROR(__xludf.DUMMYFUNCTION("""COMPUTED_VALUE"""),"T8P4") -> T8P4 | AC36: =IFERROR(__xludf.DUMMYFUNCTION("""COMPUTED_VALUE"""),0.0) -> 0
E37: =Teams!F15 -> T8P4 | F37: {=IFERROR(XLOOKUP(E37, SignupNames, SignupClubs), "Not Found")} -> Not Found | G37: =Box_B!AB24 -> 0 | AB37: =IFERROR(__xludf.DUMMYFUNCTION("""COMPUTED_VALUE"""),"T9P1") -> T9P1 | AC37: =IFERROR(__xludf.DUMMYFUNCTION("""COMPUTED_VALUE"""),0.0) -> 0
E38: =Teams!C19 -> T9P1 | F38: {=IFERROR(XLOOKUP(E38, SignupNames, SignupClubs), "Not Found")} -> Not Found | G38: =Box_C!AB6 -> 0 | AB38: =IFERROR(__xludf.DUMMYFUNCTION("""COMPUTED_VALUE"""),"T9P2") -> T9P2 | AC38: =IFERROR(__xludf.DUMMYFUNCTION("""COMPUTED_VALUE"""),0.0) -> 0
E39: =Teams!D19 -> T9P2 | F39: {=IFERROR(XLOOKUP(E39, SignupNames, SignupClubs), "Not Found")} -> Not Found | G39: =Box_C!AB7 -> 0 | AB39: =IFERROR(__xludf.DUMMYFUNCTION("""COMPUTED_VALUE"""),"T9P3") -> T9P3 | AC39: =IFERROR(__xludf.DUMMYFUNCTION("""COMPUTED_VALUE"""),0.0) -> 0
E40: =Teams!E19 -> T9P3 | F40: {=IFERROR(XLOOKUP(E40, SignupNames, SignupClubs), "Not Found")} -> Not Found | G40: =Box_C!AB8 -> 0 | AB40: =IFERROR(__xludf.DUMMYFUNCTION("""COMPUTED_VALUE"""),"T9P4") -> T9P4 | AC40: =IFERROR(__xludf.DUMMYFUNCTION("""COMPUTED_VALUE"""),0.0) -> 0
E41: =Teams!F19 -> T9P4 | F41: {=IFERROR(XLOOKUP(E41, SignupNames, SignupClubs), "Not Found")} -> Not Found | G41: =Box_C!AB9 -> 0 | AB41: =IFERROR(__xludf.DUMMYFUNCTION("""COMPUTED_VALUE"""),"T10P1") -> T10P1 | AC41: =IFERROR(__xludf.DUMMYFUNCTION("""COMPUTED_VALUE"""),0.0) -> 0
E42: =Teams!C20 -> T10P1 | F42: {=IFERROR(XLOOKUP(E42, SignupNames, SignupClubs), "Not Found")} -> Not Found | G42: =Box_C!AB11 -> 0 | AB42: =IFERROR(__xludf.DUMMYFUNCTION("""COMPUTED_VALUE"""),"T10P2") -> T10P2 | AC42: =IFERROR(__xludf.DUMMYFUNCTION("""COMPUTED_VALUE"""),0.0) -> 0
...

Sheet Test Data
A1: Name | B1: Club | C1: Sex | D1: Tennis Strength | E1: Badminton Strength | F1: Squash Strength | G1: TT Strength | I1: Courtesy of https://1000randomnames.com/ .
A2: Zoe Perry | B2: =INDIRECT("Instructions!T" & RANDBETWEEN(5,9)) | C2: =INDIRECT("Instructions!S" & RANDBETWEEN(5,10)) | D2: 8 | E2: 5 | F2: 5 | G2: 2
A3: Waylon Valencia | B3: =INDIRECT("Instructions!T" & RANDBETWEEN(5,9)) | C3: =INDIRECT("Instructions!S" & RANDBETWEEN(5,10)) | D3: 5 | E3: 4 | F3: 2 | G3: 1
A4: Maddison Merritt | B4: =INDIRECT("Instructions!T" & RANDBETWEEN(5,9)) | C4: =INDIRECT("Instructions!S" & RANDBETWEEN(5,10)) | D4: 7 | E4: 6 | F4: 4 | G4: 2
A5: Colten Mack | B5: =INDIRECT("Instructions!T" & RANDBETWEEN(5,9)) | C5: =INDIRECT("Instructions!S" & RANDBETWEEN(5,10)) | D5: 2 | E5: 3 | F5: 7 | G5: 7
A6: Nadia McLean | B6: =INDIRECT("Instructions!T" & RANDBETWEEN(5,9)) | C6: =INDIRECT("Instructions!S" & RANDBETWEEN(5,10)) | D6: =RANDBETWEEN(1, 10) -> 5 | E6: =RANDBETWEEN(1, 10) -> 4 | F6: =RANDBETWEEN(1, 10) -> 3 | G6: =RANDBETWEEN(1, 10) -> 2
A7: Crosby Brandt | B7: =INDIRECT("Instructions!T" & RANDBETWEEN(5,9)) | C7: =INDIRECT("Instructions!S" & RANDBETWEEN(5,10)) | D7: =RANDBETWEEN(1, 10) -> 3 | E7: =RANDBETWEEN(1, 10) -> 6 | F7: =RANDBETWEEN(1, 10) -> 4 | G7: =RANDBETWEEN(1, 10) -> 3
A8: Loretta Gonzales | B8: =INDIRECT("Instructions!T" & RANDBETWEEN(5,9)) | C8: =INDIRECT("Instructions!S" & RANDBETWEEN(5,10)) | D8: =RANDBETWEEN(1, 10) -> 4 | E8: =RANDBETWEEN(1, 10) -> 5 | F8: =RANDBETWEEN(1, 10) -> 7 | G8: =RANDBETWEEN(1, 10) -> 5
A9: Brayden Giles | B9: =INDIRECT("Instructions!T" & RANDBETWEEN(5,9)) | C9: =INDIRECT("Instructions!S" & RANDBETWEEN(5,10)) | D9: =RANDBETWEEN(1, 10) -> 2 | E9: =RANDBETWEEN(1, 10) -> 2 | F9: =RANDBETWEEN(1, 10) -> 9 | G9: =RANDBETWEEN(1, 10) -> 1
A10: Bailee Todd | B10: =INDIRECT("Instructions!T" & RANDBETWEEN(5,9)) | C10: =INDIRECT("Instructions!S" & RANDBETWEEN(5,10)) | D10: =RANDBETWEEN(1, 10) -> 5 | E10: =RANDBETWEEN(1, 10) -> 9 | F10: =RANDBETWEEN(1, 10) -> 6 | G10: =RANDBETWEEN(1, 10) -> 4
A11: Baylor McKinney | B11: =INDIRECT("Instructions!T" & RANDBETWEEN(5,9)) | C11: =INDIRECT("Instructions!S" & RANDBETWEEN(5,10)) | D11: =RANDBETWEEN(1, 10) -> 1 | E11: =RANDBETWEEN(1, 10) -> 3 | F11: =RANDBETWEEN(1, 10) -> 4 | G11: =RANDBETWEEN(1, 10) -> 8
A12: Gwendolyn Hickman | B12: =INDIRECT("Instructions!T" & RANDBETWEEN(5,9)) | C12: =INDIRECT("Instructions!S" & RANDBETWEEN(5,10)) | D12: =RANDBETWEEN(1, 10) -> 7 | E12: =RANDBETWEEN(1, 10) -> 8 | F12: =RANDBETWEEN(1, 10) -> 2 | G12: =RANDBETWEEN(1, 10) -> 10
A13: Jakobe Villegas | B13: =INDIRECT("Instructions!T" & RANDBETWEEN(5,9)) | C13: =INDIRECT("Instructions!S" & RANDBETWEEN(5,10)) | D13: =RANDBETWEEN(1, 10) -> 8 | E13: =RANDBETWEEN(1, 10) -> 2 | F13: =RANDBETWEEN(1, 10) -> 4 | G13: =RANDBETWEEN(1, 10) -> 9
A14: Jessie Warren | B14: =INDIRECT("Instructions!T" & RANDBETWEEN(5,9)) | C14: =INDIRECT("Instructions!S" & RANDBETWEEN(5,10)) | D14: =RANDBETWEEN(1, 10) -> 9 | E14: =RANDBETWEEN(1, 10) -> 1 | F14: =RANDBETWEEN(1, 10) -> 5 | G14: =RANDBETWEEN(1, 10) -> 6
A15: Abel Pugh | B15: =INDIRECT("Instructions!T" & RANDBETWEEN(5,9)) | C15: =INDIRECT("Instructions!S" & RANDBETWEEN(5,10)) | D15: =RANDBETWEEN(1, 10) -> 1 | E15: =RANDBETWEEN(1, 10) -> 7 | F15: =RANDBETWEEN(1, 10) -> 4 | G15: =RANDBETWEEN(1, 10) -> 3
A16: Landry Hartman | B16: =INDIRECT("Instructions!T" & RANDBETWEEN(5,9)) | C16: =INDIRECT("Instructions!S" & RANDBETWEEN(5,10)) | D16: =RANDBETWEEN(1, 10) -> 1 | E16: =RANDBETWEEN(1, 10) -> 2 | F16: =RANDBETWEEN(1, 10) -> 9 | G16: =RANDBETWEEN(1, 10) -> 9
A17: Baker Hester | B17: =INDIRECT("Instructions!T" & RANDBETWEEN(5,9)) | C17: =INDIRECT("Instructions!S" & RANDBETWEEN(5,10)) | D17: =RANDBETWEEN(1, 10) -> 9 | E17: =RANDBETWEEN(1, 10) -> 6 | F17: =RANDBETWEEN(1, 10) -> 9 | G17: =RANDBETWEEN(1, 10) -> 9
... A49: Tomas McKay | B49: =INDIRECT("Instructions!T" & RANDBETWEEN(5,9)) | C49: =INDIRECT("Instructions!S" & RANDBETWEEN(5,10)) | D49: =RANDBETWEEN(1, 10) -> 4 | E49: =RANDBETWEEN(1, 10) -> 10 | F49: =RANDBETWEEN(1, 10) -> 8 | G49: =RANDBETWEEN(1, 10) -> 2
